<?xml version="1.0" ?>
<!-- =================================================================================== -->
<!-- |    This document was autogenerated by xacro from /home/josemsotov/Desktop/Smart_GOLF_TROLLEY/dev_ws/src/my_bot/description/robot_core.xacro | -->
<!-- |    EDITING THIS FILE BY HAND IS NOT RECOMMENDED                                 | -->
<!-- =================================================================================== -->
<robot xmlns:xacro="http://www.ros.org/wiki/xacro"  name="robot">
  <!-- Specify some standard inertial calculations https://en.wikipedia.org/wiki/List_of_moments_of_inertia -->
  <!-- These make use of xacro's mathematical functionality -->
  <material name="white">
    <color rgba="1 1 1 1"/>
  </material>
  <material name="orange">
    <color rgba="1 0.3 0.1 1"/>
  </material>
  <material name="blue">
    <color rgba="0.2 0.2 1 1"/>
  </material>
  <material name="black">
    <color rgba="0 0 0 1"/>
  </material>
  <!--   BASE LINK   -->
  <link name="base_link">

    </link>
  <!--   CHASSIS LINK   -->
  <joint name="chassis_joint" type="fixed">
    <parent link="base_link"/>
    <child link="chassis"/>
    <origin xyz="0 0 0"/>
  </joint>
  <link name="chassis">
    <visual>
      <origin xyz="-0.35 0 0.2625"/>
      <geometry>
        <box size="0.7 0.71 0.525"/>
      </geometry>
      <material name="blue"/>
    </visual>
    <collision>
      <origin xyz="-0.35 0 0.2625"/>
      <geometry>
        <box size="0.7 0.71 0.525"/>
      </geometry>
    </collision>
    <inertial>
      <origin rpy="0 0 0" xyz="-0.35 0 0.2625"/>
      <mass value="1"/>
      <inertia ixx="0.6497708333333333" ixy="0.0" ixz="0.0" iyy="0.6380208333333333" iyz="0.0" izz="0.8284166666666666"/>
    </inertial>
  </link>
  <gazebo reference="chassis">
    <material>Gazebo/Blue</material>
  </gazebo>
  <!--   LEFT WHEEL LINK   -->
  <joint name="left_wheel_joint" type="continuous">
    <parent link="base_link"/>
    <child link="left_wheel"/>
    <origin xyz="0 0.355 0" rpy="${pi/2} 0 0"/>
    <axis xyz="0 0 -1"/>
  </joint>
  <link name="left_wheel">
    <visual>
      <geometry>
        <cylinder length="0.12" radius="0.11"/>
      </geometry>
      <material name="black"/>
    </visual>
    <collision>
      <geometry>
        <cylinder length="0.12" radius="0.11"/>
      </geometry>
    </collision>
    <inertial>
      <origin rpy="0 0 0" xyz="0 0 0"/>
      <mass value="1.5"/>
      <inertia ixx="0.006337499999999999" ixy="0.0" ixz="0.0" iyy="0.006337499999999999" iyz="0.0" izz="0.009075"/>
    </inertial>
  </link>
  <gazebo reference="left_wheel">
    <material>Gazebo/Black</material>
  </gazebo>
  <!--   RIGHT WHEEL LINK   -->
  <joint name="right_wheel_joint" type="continuous">
    <parent link="base_link"/>
    <child link="right_wheel"/>
    <origin xyz="0 -0.355 0" rpy="-${pi/2} 0 0"/>
    <axis xyz="0 0 1"/>
  </joint>
  <link name="right_wheel">
    <visual>
      <geometry>
         <cylinder length="0.12" radius="0.11"/>
      </geometry>
      <material name="black"/>
    </visual>
    <collision>
      <geometry>
        <cylinder length="0.12" radius="0.11"/>
      </geometry>
    </collision>
    <inertial>
      <origin rpy="0 0 0" xyz="0 0 0"/>
      <mass value="1.5"/>
      <inertia ixx="0.006337499999999999" ixy="0.0" ixz="0.0" iyy="0.006337499999999999" iyz="0.0" izz="0.009075"/>
    </inertial>
  </link>
  <gazebo reference="right_wheel">
    <material>Gazebo/Black</material>
  </gazebo>
  <!--   CASTER WHEEL LINK   -->
  <joint name="caster_joint" type="fixed">
    <parent link="chassis"/>
    <child link="caster_wheel"/>
    <origin xyz="-0.7 0 0"/>
  </joint>
  <link name="caster_wheel">
    <visual>
       <geometry>
          <sphere radius="0.11"/>
      </geometry>
      <material name="black"/>
    </visual>
    <collision>
      <geometry>
        <sphere radius="0.11"/>
      </geometry>
    </collision>
    <inertial>
      <origin rpy="0 0 0" xyz="0 0 0"/>
      <mass value="0.5"/>
      <inertia ixx="0.0024200000000000003" ixy="0.0" ixz="0.0" iyy="0.0024200000000000003" iyz="0.0" izz="0.0024200000000000003"/>
    </inertial>
  </link>
  <gazebo reference="caster_wheel">
    <material>Gazebo/Grey</material>
    <mu1 value="0.001"/>
    <mu2 value="0.001"/>
  </gazebo>
</robot>
